<?xml version="1.0" ?>
<!-- =================================================================================== -->
<!-- |    This document was autogenerated by xacro from niryo_ned.urdf.xacro           | -->
<!-- |    EDITING THIS FILE BY HAND IS NOT RECOMMENDED                                 | -->
<!-- =================================================================================== -->
<robot name="niryo_ned">
  <!-- Properties -->
  <!-- Links -->
  <link name="world"/>
  <joint name="joint_world" type="fixed">
    <parent link="world"/>
    <child link="base_link"/>
    <origin rpy="0 0 0" xyz="0 0 0"/>
  </joint>
  <link name="base_link">
    <inertial>
      <origin rpy="0 0 0" xyz="-0.00240796011216664 -0.00591764669105095 0.0515774030380053"/>
      <mass value="0.999243361008122"/>
      <inertia ixx="0.002" ixy="0.0" ixz="0.0" iyy="0.002" iyz="0.0" izz="0.004"/>
    </inertial>
    <visual>
      <origin rpy="0 0 0" xyz="0 0 0"/>
      <geometry>
        <mesh filename="package://niryo_robot_description/meshes/ned/collada/base_link.dae"/>
      </geometry>
    </visual>
    <collision>
      <origin rpy="0 0 0" xyz="0 0 0"/>
      <geometry>
        <mesh filename="package://niryo_robot_description/meshes/ned/stl/base_link.stl"/>
      </geometry>
    </collision>
  </link>
  <!--Joints -->
  <joint name="joint_1" type="revolute">
    <origin rpy="0 0 0" xyz="0 0 0.1065"/>
    <parent link="base_link"/>
    <child link="shoulder_link"/>
    <axis xyz="0 0 1"/>
    <limit effort="10.0" lower="-2.9670597283905553" upper="2.9670597283905553" velocity="2.2"/>
  </joint>
  <link name="shoulder_link">
    <inertial>
      <origin rpy="0 0 0" xyz="-0.0307310771918448 0.00581074732334248 0.0302277607274943"/>
      <mass value="0.474558968160783"/>
      <inertia ixx="0.0015" ixy="0.0" ixz="0.0" iyy="0.0015" iyz="0.0" izz="0.0015"/>
    </inertial>
    <visual>
      <origin rpy="0 0 0" xyz="0 0 0"/>
      <geometry>
        <mesh filename="package://niryo_robot_description/meshes/ned/collada/shoulder_link.dae"/>
      </geometry>
    </visual>
    <collision>
      <origin rpy="0 0 0" xyz="0 0 0"/>
      <geometry>
        <mesh filename="package://niryo_robot_description/meshes/ned/stl/shoulder_link.stl"/>
      </geometry>
    </collision>
  </link>
  <joint name="joint_2" type="revolute">
    <origin rpy="1.570796326795 -1.570796326795 0" xyz="0 0 0.065"/>
    <parent link="shoulder_link"/>
    <child link="arm_link"/>
    <axis xyz="0 0 1"/>
    <limit effort="10.0" lower="-1.9100883333827199" upper="0.6101671064972578" velocity="2.2"/>
  </joint>
  <link name="arm_link">
    <inertial>
      <origin rpy="0 0 0" xyz="0.116485160625991 -0.00141190194997476 -0.00338105503061108"/>
      <mass value="0.513332159226246"/>
      <inertia ixx="0.0015" ixy="0.0" ixz="0.0" iyy="0.0015" iyz="0.0" izz="0.0015"/>
    </inertial>
    <visual>
      <origin rpy="0 0 0" xyz="0 0 0"/>
      <geometry>
        <mesh filename="package://niryo_robot_description/meshes/ned/collada/arm_link.dae"/>
      </geometry>
    </visual>
    <collision>
      <origin rpy="0 0 0" xyz="0 0 0"/>
      <geometry>
        <mesh filename="package://niryo_robot_description/meshes/ned/stl/arm_link.stl"/>
      </geometry>
    </collision>
  </link>
  <joint name="joint_3" type="revolute">
    <origin rpy="0 0 -1.570796326795" xyz="0.221 -0.012 0"/>
    <parent link="arm_link"/>
    <child link="elbow_link"/>
    <axis xyz="0 0 1"/>
    <limit effort="7.0" lower="-1.3400637996813345" upper="1.5700981950942021" velocity="2.0"/>
  </joint>
  <link name="elbow_link">
    <inertial>
      <origin rpy="0 0 0" xyz="0.00840548736069937 0.0235132719991579 0.00139784606943909"/>
      <mass value="0.201038841892435"/>
      <inertia ixx="0.0015" ixy="0.0" ixz="0.0" iyy="0.0015" iyz="0.0" izz="0.0015"/>
    </inertial>
    <visual>
      <origin rpy="0 0 0" xyz="0 0 0"/>
      <geometry>
        <mesh filename="package://niryo_robot_description/meshes/ned/collada/elbow_link.dae"/>
      </geometry>
    </visual>
    <collision>
      <origin rpy="0 0 0" xyz="0 0 0"/>
      <geometry>
        <mesh filename="package://niryo_robot_description/meshes/ned/stl/elbow_link.stl"/>
      </geometry>
    </collision>
  </link>
  <joint name="joint_4" type="revolute">
    <origin rpy="0 1.570796326795 0" xyz="0.047 0.0325 0"/>
    <parent link="elbow_link"/>
    <child link=""/>
    <axis xyz="0 0 1"/>
    <limit effort="7.0" lower="-2.090031779263347" upper="2.090031779263347" velocity="2.0"/>
  </joint>
</robot>

